Workbook

Sheet Σύνοψη
A1: Κόστος μετακίνησης Αθήνα ↔ Λιβαδειά με αυτοκίνητο
A2: Toyota Yaris 2026 Hybrid 130 · Fast Pass Νέα Οδός Frequent All 2 · Οκτώβριος 2026
A4: ="1. Τελική σύγκριση – μέσος μήνας ("&Παραδοχές!C12&" πήγαινε–έλα)" -> 1. Τελική σύγκριση – μέσος μήνας (13 πήγαινε–έλα)
A5: Σενάριο | B5: Διαδρομή | C5: Καύσιμο (€) | D5: Διόδια χωρίς έκπτωση (€) | E5: Διόδια με Frequent All 2 (€) | F5: Σύνολο / μήνα (€) | G5: Διαφορά από Γ (€) | H5: Σύνολο / έτος (€)
A6: Α. Αφίδνες → Πλευρ. Θήβας → Αφίδνες | B6: Μετωπικός Αφιδνών + πλευρικός Θήβας και στις δύο κατευθύνσεις | C6: =Παραδοχές!$C$14*Παραδοχές!$C$12 -> 396.2946 | D6: =SUM('Υπολογισμός διοδίων'!E6:E9) -> 148.2 | E6: =SUM('Υπολογισμός διοδίων'!G6:G9) -> 135.945 | F6: =C6+E6 -> 532.2396 | G6: =F6-$F$7 -> 34.5 | H6: =F6*12 -> 6386.8752
A7: Γ. Πλευρικά → Πλευρ. Θήβας + Αφίδνες | B7: Προς Λιβαδειά: πλευρ. Οινοφύτων + Θήβας. Προς Αθήνα: πλευρ. Θήβας + μετωπ. Αφιδνών | C7: =Παραδοχές!$C$14*Παραδοχές!$C$12 -> 396.2946 | D7: =SUM('Υπολογισμός διοδίων'!M6:M9) -> 107.9 | E7: =SUM('Υπολογισμός διοδίων'!O6:O9) -> 101.445 | F7: =C7+E7 -> 497.7396 | G7: =F7-$F$7 -> 0 | H7: =F7*12 -> 5972.8752
A8: Β. Μετωπικά → Μετωπικά | B8: Μετωπικοί Αφιδνών & Θήβας και στις δύο κατευθύνσεις | C8: =Παραδοχές!$C$14*Παραδοχές!$C$12 -> 396.2946 | D8: =SUM('Υπολογισμός διοδίων'!I6:I9) -> 219.7 | E8: =SUM('Υπολογισμός διοδίων'!K6:K9) -> 201.5325 | F8: =C8+E8 -> 597.8271 | G8: =F8-$F$7 -> 100.0875 | H8: =F8*12 -> 7173.9252
A10: ="2. Διόδια ανά σταθμό – μέσος μήνας ("&Παραδοχές!C12&" πήγαινε–έλα)" -> 2. Διόδια ανά σταθμό – μέσος μήνας (13 πήγαινε–έλα)
A11: Σταθμός | B11: Τιμή (€) | C11: Α. Αφίδνες → Πλευρ. Θήβας → Αφίδνες | F11: Γ. Πλευρικά → Πλευρ. Θήβας + Αφίδνες | I11: Β. Μετωπικά → Μετωπικά
C12: Διελεύσεις | D12: Χωρίς έκπτωση (€) | E12: Με έκπτωση (€) | F12: Διελεύσεις | G12: Χωρίς έκπτωση (€) | H12: Με έκπτωση (€) | I12: Διελεύσεις | J12: Χωρίς έκπτωση (€) | K12: Με έκπτωση (€)
A13: =Παραδοχές!B18 -> Πλευρικός Οινοφύτων | B13: =Παραδοχές!C18 -> 0.8 | C13: ='Υπολογισμός διοδίων'!D6 -> 0 | D13: ='Υπολογισμός διοδίων'!E6 -> 0 | E13: ='Υπολογισμός διοδίων'!G6 -> 0 | F13: ='Υπολογισμός διοδίων'!L6 -> 13 | G13: ='Υπολογισμός διοδίων'!M6 -> 10.4 | H13: ='Υπολογισμός διοδίων'!O6 -> 9.96 | I13: ='Υπολογισμός διοδίων'!H6 -> 0 | J13: ='Υπολογισμός διοδίων'!I6 -> 0 | K13: ='Υπολογισμός διοδίων'!K6 -> 0
A14: =Παραδοχές!B19 -> Πλευρικός Θήβας | B14: =Παραδοχές!C19 -> 1.8 | C14: ='Υπολογισμός διοδίων'!D7 -> 26 | D14: ='Υπολογισμός διοδίων'!E7 -> 46.8 | E14: ='Υπολογισμός διοδίων'!G7 -> 42.93 | F14: ='Υπολογισμός διοδίων'!L7 -> 26 | G14: ='Υπολογισμός διοδίων'!M7 -> 46.8 | H14: ='Υπολογισμός διοδίων'!O7 -> 42.93 | I14: ='Υπολογισμός διοδίων'!H7 -> 0 | J14: ='Υπολογισμός διοδίων'!I7 -> 0 | K14: ='Υπολογισμός διοδίων'!K7 -> 0
A15: =Παραδοχές!B20 -> Μετωπικός Αφιδνών | B15: =Παραδοχές!C20 -> 3.9 | C15: ='Υπολογισμός διοδίων'!D8 -> 26 | D15: ='Υπολογισμός διοδίων'!E8 -> 101.4 | E15: ='Υπολογισμός διοδίων'!G8 -> 93.015 | F15: ='Υπολογισμός διοδίων'!L8 -> 13 | G15: ='Υπολογισμός διοδίων'!M8 -> 50.7 | H15: ='Υπολογισμός διοδίων'!O8 -> 48.555 | I15: ='Υπολογισμός διοδίων'!H8 -> 26 | J15: ='Υπολογισμός διοδίων'!I8 -> 101.4 | K15: ='Υπολογισμός διοδίων'!K8 -> 93.015
A16: =Παραδοχές!B21 -> Μετωπικός Θήβας | B16: =Παραδοχές!C21 -> 4.55 | C16: ='Υπολογισμός διοδίων'!D9 -> 0 | D16: ='Υπολογισμός διοδίων'!E9 -> 0 | E16: ='Υπολογισμός διοδίων'!G9 -> 0 | F16: ='Υπολογισμός διοδίων'!L9 -> 0 | G16: ='Υπολογισμός διοδίων'!M9 -> 0 | H16: ='Υπολογισμός διοδίων'!O9 -> 0 | I16: ='Υπολογισμός διοδίων'!H9 -> 26 | J16: ='Υπολογισμός διοδίων'!I9 -> 118.3 | K16: ='Υπολογισμός διοδίων'!K9 -> 108.5175
A17: Σύνολο διοδίων | D17: =SUM(D13:D16) -> 148.2 | E17: =SUM(E13:E16) -> 135.945 | G17: =SUM(G13:G16) -> 107.9 | H17: =SUM(H13:H16) -> 101.445 | J17: =SUM(J13:J16) -> 219.7 | K17: =SUM(K13:K16) -> 201.5325
A19: 3. Ανάλυση ανά ημερολογιακό μήνα (η έκπτωση μηδενίζεται κάθε μήνα)
A20: Μήνας | B20: Πήγαινε–έλα / μήνα | C20: Καύσιμο (€) | D20: Α. Αφίδνες → Πλευρ. Θήβας → Αφίδνες (€) | E20: Γ. Πλευρικά → Πλευρ. Θήβας + Αφίδνες (€) | F20: Β. Μετωπικά → Μετωπικά (€) | G20: Α − Γ (€) | H20: Β − Γ (€)
A21: Μήνας με 12 διαδρομές | B21: 12 | C21: =B21*Παραδοχές!$C$14 -> 365.8104 | D21: =C21+SUM('Υπολογισμός διοδίων'!G10:G13) -> 492.0654 | E21: =C21+SUM('Υπολογισμός διοδίων'!O10:O13) -> 459.9654 | F21: =C21+SUM('Υπολογισμός διοδίων'!K10:K13) -> 552.9779 | G21: =D21-E21 -> 32.1 | H21: =F21-E21 -> 93.0125
A22: Μήνας με 13 διαδρομές | B22: 13 | C22: =B22*Παραδοχές!$C$14 -> 396.2946 | D22: =C22+SUM('Υπολογισμός διοδίων'!G14:G17) -> 532.2396 | E22: =C22+SUM('Υπολογισμός διοδίων'!O14:O17) -> 497.7396 | F22: =C22+SUM('Υπολογισμός διοδίων'!K14:K17) -> 597.8271 | G22: =D22-E22 -> 34.5 | H22: =F22-E22 -> 100.0875
A23: Μήνας με 14 διαδρομές | B23: 14 | C23: =B23*Παραδοχές!$C$14 -> 426.7788 | D23: =C23+SUM('Υπολογισμός διοδίων'!G18:G21) -> 572.4138 | E23: =C23+SUM('Υπολογισμός διοδίων'!O18:O21) -> 535.5138 | F23: =C23+SUM('Υπολογισμός διοδίων'!K18:K21) -> 642.6763 | G23: =D23-E23 -> 36.9 | H23: =F23-E23 -> 107.1625
A24: Μήνας με 15 διαδρομές | B24: 15 | C24: =B24*Παραδοχές!$C$14 -> 457.263 | D24: =C24+SUM('Υπολογισμός διοδίων'!G22:G25) -> 612.588 | E24: =C24+SUM('Υπολογισμός διοδίων'!O22:O25) -> 573.288 | F24: =C24+SUM('Υπολογισμός διοδίων'!K22:K25) -> 687.5255 | G24: =D24-E24 -> 39.3 | H24: =F24-E24 -> 114.2375
A25: Ο αριθμός πήγαινε–έλα ανά μήνα (μπλε, κίτρινο φόντο) μπορεί να αλλάξει.
A27: Υποσημειώσεις – Παραδοχές
A28: ¹ Αυτοκίνητο | B28: =Παραδοχές!C5 -> Toyota Yaris 2026 Hybrid 130
A29: ² Ισχύς | B29: =Παραδοχές!C6 -> 130 | C29: Έκδοση Hybrid 130
A30: ³ Τιμή βενζίνης 95 | B30: =Παραδοχές!C7 -> 2.3 | C30: Μέση τιμή περιόδου
A31: ⁴ Μέση κατανάλωση | B31: =Παραδοχές!C8 -> 4.7 | C31: Πραγματική κατανάλωση στη διαδρομή (όχι WLTP)
A32: ⁵ Απόσταση | B32: =Παραδοχές!C9 -> 141 | C32: Ανά κατεύθυνση, ίδια σε όλα τα σενάρια
A33: ⁶ Συχνότητα | B33: =Παραδοχές!C10 -> 3 | C33: Μέσος μήνας = 3 × 52 / 12 = 13 πήγαινε–έλα
A34: ⁷ Διόδια (κατηγορία 2 – ΙΧ) | B34: Οινόφυτα 0,80 € · Θήβα πλευρ. 1,80 € | C34: Αφίδνες 3,90 € · Θήβα μετωπ. 4,55 € (επιβεβαιωμένες τιμές)
A35: ⁸ Πρόγραμμα e-pass | B35: Fast Pass Νέα Οδός Frequent All 2 | C35: Έκπτωση ανά σταθμό, ανά ημερολογιακό μήνα: 1–5: 0%, 6–10: 5%, 11–20: 10%, 21–30: 15%, 31–40: 20%, 41–50: 40%, 51–60: 50%
A36: ⁹ Εφαρμογή έκπτωσης | B36: Κλιμακωτή | C36: Κάθε ποσοστό μόνο για τις διελεύσεις της κλίμακάς του. Πλευρικός και μετωπικός Θήβας μετρούν ως ξεχωριστοί σταθμοί. Μετρούν και οι δύο κατευθύνσεις.
A37: ¹⁰ Στρογγυλοποίηση | B37: ± λίγα λεπτά | C37: Η χρέωση ανά διέλευση μπορεί να στρογγυλοποιείται διαφορετικά από τη Νέα Οδό.
A38: ¹¹ Δεν περιλαμβάνονται | B38: Φθορά, service, ελαστικά, απόσβεση, χρόνος | C38: Το κόστος αφορά μόνο καύσιμα και διόδια.

Sheet Παραδοχές
B1: Παραδοχές υπολογισμού
B2: Μπλε κείμενο σε κίτρινο φόντο = στοιχεία εισόδου (μπορούν να αλλάξουν). Μαύρο = τύποι.
B3: Γενικά στοιχεία
B4: Στοιχείο | C4: Τιμή | D4: Μονάδα | E4: Πηγή / σχόλιο
B5: Αυτοκίνητο | C5: Toyota Yaris 2026 Hybrid 130 | E5: Δήλωση χρήστη
B6: Ισχύς (ίπποι συστήματος) | C6: 130 | D6: PS | E6: Έκδοση Hybrid 130
B7: Τιμή βενζίνης 95 οκτανίων | C7: 2.3 | D7: €/L | E7: Μέση τιμή περιόδου, δήλωση χρήστη
B8: Μέση κατανάλωση στη διαδρομή | C8: 4.7 | D8: L/100 km | E8: Πραγματική κατανάλωση (όχι WLTP), δήλωση χρήστη
B9: Απόσταση ανά κατεύθυνση | C9: 141 | D9: km | E9: Ίδια σε όλα τα σενάρια
B10: Πήγαινε–έλα ανά εβδομάδα | C10: 3 | D10: διαδρομές | E10: Δήλωση χρήστη
B11: Εβδομάδες ανά έτος | C11: 52 | D11: εβδομάδες
B12: Πήγαινε–έλα ανά μέσο μήνα | C12: =ROUND(C10*C11/12,0) -> 13 | D12: διαδρομές | E12: Πήγαινε–έλα/εβδομάδα × εβδομάδες / 12
B13: Χιλιόμετρα ανά πήγαινε–έλα | C13: =2*C9 -> 282 | D13: km | E13: 2 × απόσταση ανά κατεύθυνση
B14: Κόστος καυσίμου ανά πήγαινε–έλα | C14: =C13*C8/100*C7 -> 30.4842 | D14: € | E14: km × κατανάλωση / 100 × τιμή βενζίνης
B16: Τιμές διοδίων Νέας Οδού (κατηγορία 2 – ΙΧ)
B17: Σταθμός | C17: Τιμή (€) | D17: Τύπος | E17: Πηγή / σχόλιο
B18: Πλευρικός Οινοφύτων | C18: 0.8 | D18: Πλευρικός | E18: Τιμή επιβεβαιωμένη από τον χρήστη
B19: Πλευρικός Θήβας | C19: 1.8 | D19: Πλευρικός | E19: Τιμή επιβεβαιωμένη από τον χρήστη
B20: Μετωπικός Αφιδνών | C20: 3.9 | D20: Μετωπικός | E20: Τιμή επιβεβαιωμένη από τον χρήστη
B21: Μετωπικός Θήβας | C21: 4.55 | D21: Μετωπικός | E21: Τιμή επιβεβαιωμένη από τον χρήστη
B23: Διελεύσεις ανά σταθμό σε ένα πήγαινε–έλα
B24: Σταθμός | C24: Σενάριο Α | D24: Σενάριο Β | E24: Σενάριο Γ
B25: =B18 -> Πλευρικός Οινοφύτων | C25: 0 | D25: 0 | E25: 1
B26: =B19 -> Πλευρικός Θήβας | C26: 2 | D26: 0 | E26: 2
B27: =B20 -> Μετωπικός Αφιδνών | C27: 2 | D27: 2 | E27: 1
B28: =B21 -> Μετωπικός Θήβας | C28: 0 | D28: 2 | E28: 0
B29: Διόδια ανά πήγαινε–έλα χωρίς έκπτωση (€) | C29: =SUMPRODUCT($C$18:$C$21,C25:C28) -> 11.4 | D29: =SUMPRODUCT($C$18:$C$21,D25:D28) -> 16.9 | E29: =SUMPRODUCT($C$18:$C$21,E25:E28) -> 8.3
B31: Περιγραφή σεναρίων
B32: Σενάριο | C32: Διαδρομή
B33: Α. Αφίδνες → Πλευρ. Θήβας → Αφίδνες | C33: Αθήνα → Α1 → μετωπικός Αφιδνών → πλευρικός Θήβας → Λιβαδειά, και αντίστροφα
B34: Β. Μετωπικά → Μετωπικά | C34: Α1 με μετωπικούς Αφιδνών και Θήβας και στις δύο κατευθύνσεις
B35: Γ. Πλευρικά → Πλευρ. Θήβας + Αφίδνες | C35: Προς Λιβαδειά: πλευρικός Οινοφύτων + πλευρικός Θήβας. Προς Αθήνα: πλευρικός Θήβας + Α1 μέχρι Αθήνα με μετωπικό Αφιδνών
B37: Fast Pass Νέα Οδός – πρόγραμμα Frequent All 2
B38: Από διέλευση | C38: Έως διέλευση | D38: Έκπτωση
B39: 1 | C39: 5 | D39: 0
B40: 6 | C40: 10 | D40: 0.05
B41: 11 | C41: 20 | D41: 0.1
B42: 21 | C42: 30 | D42: 0.15
B43: 31 | C43: 40 | D43: 0.2
B44: 41 | C44: 50 | D44: 0.4
...

Sheet Υπολογισμός διοδίων
A1: Υπολογισμός διοδίων με κλιμακωτή έκπτωση Frequent All 2
A2: Χρεώσιμες διελεύσεις = διελεύσεις − Σ(έκπτωση κλίμακας × διελεύσεις μέσα στην κλίμακα). Κόστος με έκπτωση = τιμή × χρεώσιμες διελεύσεις.
D4: Σενάριο Α – Αφίδνες → Πλευρ. Θήβας → Αφίδνες | H4: Σενάριο Β – Μετωπικά → Μετωπικά | L4: Σενάριο Γ – Πλευρικά → Πλευρ. Θήβας + Αφίδνες
A5: Πήγαινε–έλα / μήνα | B5: Σταθμός | C5: Τιμή (€) | D5: Διελεύσεις / μήνα | E5: Χωρίς έκπτωση (€) | F5: Χρεώσιμες διελεύσεις | G5: Με έκπτωση (€) | H5: Διελεύσεις / μήνα | I5: Χωρίς έκπτωση (€) | J5: Χρεώσιμες διελεύσεις | K5: Με έκπτωση (€) | L5: Διελεύσεις / μήνα | M5: Χωρίς έκπτωση (€) | N5: Χρεώσιμες διελεύσεις | O5: Με έκπτωση (€)
A6: =Παραδοχές!$C$12 -> 13 | B6: =Παραδοχές!$B$18 -> Πλευρικός Οινοφύτων | C6: =Παραδοχές!$C$18 -> 0.8 | D6: =$A6*Παραδοχές!$C$25 -> 0 | E6: =D6*$C6 -> 0 | F6: =D6-SUMPRODUCT(Παραδοχές!$D$39:$D$45,(D6>Παραδοχές!$C$39:$C$45)*(Παραδοχές!$C$39:$C$45-Παραδοχές!$B$39:$B$45+1)+(D6>=Παραδοχές!$B$39:$B$45)*(D6<=Παραδοχές!$C$39:$C$45)*(D6-Παραδοχές!$B$39:$B$45+1)) -> 0 | G6: =F6*$C6 -> 0 | H6: =$A6*Παραδοχές!$D$25 -> 0 | I6: =H6*$C6 -> 0 | J6: =H6-SUMPRODUCT(Παραδοχές!$D$39:$D$45,(H6>Παραδοχές!$C$39:$C$45)*(Παραδοχές!$C$39:$C$45-Παραδοχές!$B$39:$B$45+1)+(H6>=Παραδοχές!$B$39:$B$45)*(H6<=Παραδοχές!$C$39:$C$45)*(H6-Παραδοχές!$B$39:$B$45+1)) -> 0 | K6: =J6*$C6 -> 0 | L6: =$A6*Παραδοχές!$E$25 -> 13 | M6: =L6*$C6 -> 10.4 | N6: =L6-SUMPRODUCT(Παραδοχές!$D$39:$D$45,(L6>Παραδοχές!$C$39:$C$45)*(Παραδοχές!$C$39:$C$45-Παραδοχές!$B$39:$B$45+1)+(L6>=Παραδοχές!$B$39:$B$45)*(L6<=Παραδοχές!$C$39:$C$45)*(L6-Παραδοχές!$B$39:$B$45+1)) -> 12.45 | O6: =N6*$C6 -> 9.96
A7: =Παραδοχές!$C$12 -> 13 | B7: =Παραδοχές!$B$19 -> Πλευρικός Θήβας | C7: =Παραδοχές!$C$19 -> 1.8 | D7: =$A7*Παραδοχές!$C$26 -> 26 | E7: =D7*$C7 -> 46.8 | F7: =D7-SUMPRODUCT(Παραδοχές!$D$39:$D$45,(D7>Παραδοχές!$C$39:$C$45)*(Παραδοχές!$C$39:$C$45-Παραδοχές!$B$39:$B$45+1)+(D7>=Παραδοχές!$B$39:$B$45)*(D7<=Παραδοχές!$C$39:$C$45)*(D7-Παραδοχές!$B$39:$B$45+1)) -> 23.85 | G7: =F7*$C7 -> 42.93 | H7: =$A7*Παραδοχές!$D$26 -> 0 | I7: =H7*$C7 -> 0 | J7: =H7-SUMPRODUCT(Παραδοχές!$D$39:$D$45,(H7>Παραδοχές!$C$39:$C$45)*(Παραδοχές!$C$39:$C$45-Παραδοχές!$B$39:$B$45+1)+(H7>=Παραδοχές!$B$39:$B$45)*(H7<=Παραδοχές!$C$39:$C$45)*(H7-Παραδοχές!$B$39:$B$45+1)) -> 0 | K7: =J7*$C7 -> 0 | L7: =$A7*Παραδοχές!$E$26 -> 26 | M7: =L7*$C7 -> 46.8 | N7: =L7-SUMPRODUCT(Παραδοχές!$D$39:$D$45,(L7>Παραδοχές!$C$39:$C$45)*(Παραδοχές!$C$39:$C$45-Παραδοχές!$B$39:$B$45+1)+(L7>=Παραδοχές!$B$39:$B$45)*(L7<=Παραδοχές!$C$39:$C$45)*(L7-Παραδοχές!$B$39:$B$45+1)) -> 23.85 | O7: =N7*$C7 -> 42.93
A8: =Παραδοχές!$C$12 -> 13 | B8: =Παραδοχές!$B$20 -> Μετωπικός Αφιδνών | C8: =Παραδοχές!$C$20 -> 3.9 | D8: =$A8*Παραδοχές!$C$27 -> 26 | E8: =D8*$C8 -> 101.4 | F8: =D8-SUMPRODUCT(Παραδοχές!$D$39:$D$45,(D8>Παραδοχές!$C$39:$C$45)*(Παραδοχές!$C$39:$C$45-Παραδοχές!$B$39:$B$45+1)+(D8>=Παραδοχές!$B$39:$B$45)*(D8<=Παραδοχές!$C$39:$C$45)*(D8-Παραδοχές!$B$39:$B$45+1)) -> 23.85 | G8: =F8*$C8 -> 93.015 | H8: =$A8*Παραδοχές!$D$27 -> 26 | I8: =H8*$C8 -> 101.4 | J8: =H8-SUMPRODUCT(Παραδοχές!$D$39:$D$45,(H8>Παραδοχές!$C$39:$C$45)*(Παραδοχές!$C$39:$C$45-Παραδοχές!$B$39:$B$45+1)+(H8>=Παραδοχές!$B$39:$B$45)*(H8<=Παραδοχές!$C$39:$C$45)*(H8-Παραδοχές!$B$39:$B$45+1)) -> 23.85 | K8: =J8*$C8 -> 93.015 | L8: =$A8*Παραδοχές!$E$27 -> 13 | M8: =L8*$C8 -> 50.7 | N8: =L8-SUMPRODUCT(Παραδοχές!$D$39:$D$45,(L8>Παραδοχές!$C$39:$C$45)*(Παραδοχές!$C$39:$C$45-Παραδοχές!$B$39:$B$45+1)+(L8>=Παραδοχές!$B$39:$B$45)*(L8<=Παραδοχές!$C$39:$C$45)*(L8-Παραδοχές!$B$39:$B$45+1)) -> 12.45 | O8: =N8*$C8 -> 48.555
A9: =Παραδοχές!$C$12 -> 13 | B9: =Παραδοχές!$B$21 -> Μετωπικός Θήβας | C9: =Παραδοχές!$C$21 -> 4.55 | D9: =$A9*Παραδοχές!$C$28 -> 0 | E9: =D9*$C9 -> 0 | F9: =D9-SUMPRODUCT(Παραδοχές!$D$39:$D$45,(D9>Παραδοχές!$C$39:$C$45)*(Παραδοχές!$C$39:$C$45-Παραδοχές!$B$39:$B$45+1)+(D9>=Παραδοχές!$B$39:$B$45)*(D9<=Παραδοχές!$C$39:$C$45)*(D9-Παραδοχές!$B$39:$B$45+1)) -> 0 | G9: =F9*$C9 -> 0 | H9: =$A9*Παραδοχές!$D$28 -> 26 | I9: =H9*$C9 -> 118.3 | J9: =H9-SUMPRODUCT(Παραδοχές!$D$39:$D$45,(H9>Παραδοχές!$C$39:$C$45)*(Παραδοχές!$C$39:$C$45-Παραδοχές!$B$39:$B$45+1)+(H9>=Παραδοχές!$B$39:$B$45)*(H9<=Παραδοχές!$C$39:$C$45)*(H9-Παραδοχές!$B$39:$B$45+1)) -> 23.85 | K9: =J9*$C9 -> 108.5175 | L9: =$A9*Παραδοχές!$E$28 -> 0 | M9: =L9*$C9 -> 0 | N9: =L9-SUMPRODUCT(Παραδοχές!$D$39:$D$45,(L9>Παραδοχές!$C$39:$C$45)*(Παραδοχές!$C$39:$C$45-Παραδοχές!$B$39:$B$45+1)+(L9>=Παραδοχές!$B$39:$B$45)*(L9<=Παραδοχές!$C$39:$C$45)*(L9-Παραδοχές!$B$39:$B$45+1)) -> 0 | O9: =N9*$C9 -> 0
A10: =Σύνοψη!$B$21 -> 12 | B10: =Παραδοχές!$B$18 -> Πλευρικός Οινοφύτων | C10: =Παραδοχές!$C$18 -> 0.8 | D10: =$A10*Παραδοχές!$C$25 -> 0 | E10: =D10*$C10 -> 0 | F10: =D10-SUMPRODUCT(Παραδοχές!$D$39:$D$45,(D10>Παραδοχές!$C$39:$C$45)*(Παραδοχές!$C$39:$C$45-Παραδοχές!$B$39:$B$45+1)+(D10>=Παραδοχές!$B$39:$B$45)*(D10<=Παραδοχές!$C$39:$C$45)*(D10-Παραδοχές!$B$39:$B$45+1)) -> 0 | G10: =F10*$C10 -> 0 | H10: =$A10*Παραδοχές!$D$25 -> 0 | I10: =H10*$C10 -> 0 | J10: =H10-SUMPRODUCT(Παραδοχές!$D$39:$D$45,(H10>Παραδοχές!$C$39:$C$45)*(Παραδοχές!$C$39:$C$45-Παραδοχές!$B$39:$B$45+1)+(H10>=Παραδοχές!$B$39:$B$45)*(H10<=Παραδοχές!$C$39:$C$45)*(H10-Παραδοχές!$B$39:$B$45+1)) -> 0 | K10: =J10*$C10 -> 0 | L10: =$A10*Παραδοχές!$E$25 -> 12 | M10: =L10*$C10 -> 9.6 | N10: =L10-SUMPRODUCT(Παραδοχές!$D$39:$D$45,(L10>Παραδοχές!$C$39:$C$45)*(Παραδοχές!$C$39:$C$45-Παραδοχές!$B$39:$B$45+1)+(L10>=Παραδοχές!$B$39:$B$45)*(L10<=Παραδοχές!$C$39:$C$45)*(L10-Παραδοχές!$B$39:$B$45+1)) -> 11.55 | O10: =N10*$C10 -> 9.24
A11: =Σύνοψη!$B$21 -> 12 | B11: =Παραδοχές!$B$19 -> Πλευρικός Θήβας | C11: =Παραδοχές!$C$19 -> 1.8 | D11: =$A11*Παραδοχές!$C$26 -> 24 | E11: =D11*$C11 -> 43.2 | F11: =D11-SUMPRODUCT(Παραδοχές!$D$39:$D$45,(D11>Παραδοχές!$C$39:$C$45)*(Παραδοχές!$C$39:$C$45-Παραδοχές!$B$39:$B$45+1)+(D11>=Παραδοχές!$B$39:$B$45)*(D11<=Παραδοχές!$C$39:$C$45)*(D11-Παραδοχές!$B$39:$B$45+1)) -> 22.15 | G11: =F11*$C11 -> 39.87 | H11: =$A11*Παραδοχές!$D$26 -> 0 | I11: =H11*$C11 -> 0 | J11: =H11-SUMPRODUCT(Παραδοχές!$D$39:$D$45,(H11>Παραδοχές!$C$39:$C$45)*(Παραδοχές!$C$39:$C$45-Παραδοχές!$B$39:$B$45+1)+(H11>=Παραδοχές!$B$39:$B$45)*(H11<=Παραδοχές!$C$39:$C$45)*(H11-Παραδοχές!$B$39:$B$45+1)) -> 0 | K11: =J11*$C11 -> 0 | L11: =$A11*Παραδοχές!$E$26 -> 24 | M11: =L11*$C11 -> 43.2 | N11: =L11-SUMPRODUCT(Παραδοχές!$D$39:$D$45,(L11>Παραδοχές!$C$39:$C$45)*(Παραδοχές!$C$39:$C$45-Παραδοχές!$B$39:$B$45+1)+(L11>=Παραδοχές!$B$39:$B$45)*(L11<=Παραδοχές!$C$39:$C$45)*(L11-Παραδοχές!$B$39:$B$45+1)) -> 22.15 | O11: =N11*$C11 -> 39.87
A12: =Σύνοψη!$B$21 -> 12 | B12: =Παραδοχές!$B$20 -> Μετωπικός Αφιδνών | C12: =Παραδοχές!$C$20 -> 3.9 | D12: =$A12*Παραδοχές!$C$27 -> 24 | E12: =D12*$C12 -> 93.6 | F12: =D12-SUMPRODUCT(Παραδοχές!$D$39:$D$45,(D12>Παραδοχές!$C$39:$C$45)*(Παραδοχές!$C$39:$C$45-Παραδοχές!$B$39:$B$45+1)+(D12>=Παραδοχές!$B$39:$B$45)*(D12<=Παραδοχές!$C$39:$C$45)*(D12-Παραδοχές!$B$39:$B$45+1)) -> 22.15 | G12: =F12*$C12 -> 86.385 | H12: =$A12*Παραδοχές!$D$27 -> 24 | I12: =H12*$C12 -> 93.6 | J12: =H12-SUMPRODUCT(Παραδοχές!$D$39:$D$45,(H12>Παραδοχές!$C$39:$C$45)*(Παραδοχές!$C$39:$C$45-Παραδοχές!$B$39:$B$45+1)+(H12>=Παραδοχές!$B$39:$B$45)*(H12<=Παραδοχές!$C$39:$C$45)*(H12-Παραδοχές!$B$39:$B$45+1)) -> 22.15 | K12: =J12*$C12 -> 86.385 | L12: =$A12*Παραδοχές!$E$27 -> 12 | M12: =L12*$C12 -> 46.8 | N12: =L12-SUMPRODUCT(Παραδοχές!$D$39:$D$45,(L12>Παραδοχές!$C$39:$C$45)*(Παραδοχές!$C$39:$C$45-Παραδοχές!$B$39:$B$45+1)+(L12>=Παραδοχές!$B$39:$B$45)*(L12<=Παραδοχές!$C$39:$C$45)*(L12-Παραδοχές!$B$39:$B$45+1)) -> 11.55 | O12: =N12*$C12 -> 45.045
A13: =Σύνοψη!$B$21 -> 12 | B13: =Παραδοχές!$B$21 -> Μετωπικός Θήβας | C13: =Παραδοχές!$C$21 -> 4.55 | D13: =$A13*Παραδοχές!$C$28 -> 0 | E13: =D13*$C13 -> 0 | F13: =D13-SUMPRODUCT(Παραδοχές!$D$39:$D$45,(D13>Παραδοχές!$C$39:$C$45)*(Παραδοχές!$C$39:$C$45-Παραδοχές!$B$39:$B$45+1)+(D13>=Παραδοχές!$B$39:$B$45)*(D13<=Παραδοχές!$C$39:$C$45)*(D13-Παραδοχές!$B$39:$B$45+1)) -> 0 | G13: =F13*$C13 -> 0 | H13: =$A13*Παραδοχές!$D$28 -> 24 | I13: =H13*$C13 -> 109.2 | J13: =H13-SUMPRODUCT(Παραδοχές!$D$39:$D$45,(H13>Παραδοχές!$C$39:$C$45)*(Παραδοχές!$C$39:$C$45-Παραδοχές!$B$39:$B$45+1)+(H13>=Παραδοχές!$B$39:$B$45)*(H13<=Παραδοχές!$C$39:$C$45)*(H13-Παραδοχές!$B$39:$B$45+1)) -> 22.15 | K13: =J13*$C13 -> 100.7825 | L13: =$A13*Παραδοχές!$E$28 -> 0 | M13: =L13*$C13 -> 0 | N13: =L13-SUMPRODUCT(Παραδοχές!$D$39:$D$45,(L13>Παραδοχές!$C$39:$C$45)*(Παραδοχές!$C$39:$C$45-Παραδοχές!$B$39:$B$45+1)+(L13>=Παραδοχές!$B$39:$B$45)*(L13<=Παραδοχές!$C$39:$C$45)*(L13-Παραδοχές!$B$39:$B$45+1)) -> 0 | O13: =N13*$C13 -> 0
A14: =Σύνοψη!$B$22 -> 13 | B14: =Παραδοχές!$B$18 -> Πλευρικός Οινοφύτων | C14: =Παραδοχές!$C$18 -> 0.8 | D14: =$A14*Παραδοχές!$C$25 -> 0 | E14: =D14*$C14 -> 0 | F14: =D14-SUMPRODUCT(Παραδοχές!$D$39:$D$45,(D14>Παραδοχές!$C$39:$C$45)*(Παραδοχές!$C$39:$C$45-Παραδοχές!$B$39:$B$45+1)+(D14>=Παραδοχές!$B$39:$B$45)*(D14<=Παραδοχές!$C$39:$C$45)*(D14-Παραδοχές!$B$39:$B$45+1)) -> 0 | G14: =F14*$C14 -> 0 | H14: =$A14*Παραδοχές!$D$25 -> 0 | I14: =H14*$C14 -> 0 | J14: =H14-SUMPRODUCT(Παραδοχές!$D$39:$D$45,(H14>Παραδοχές!$C$39:$C$45)*(Παραδοχές!$C$39:$C$45-Παραδοχές!$B$39:$B$45+1)+(H14>=Παραδοχές!$B$39:$B$45)*(H14<=Παραδοχές!$C$39:$C$45)*(H14-Παραδοχές!$B$39:$B$45+1)) -> 0 | K14: =J14*$C14 -> 0 | L14: =$A14*Παραδοχές!$E$25 -> 13 | M14: =L14*$C14 -> 10.4 | N14: =L14-SUMPRODUCT(Παραδοχές!$D$39:$D$45,(L14>Παραδοχές!$C$39:$C$45)*(Παραδοχές!$C$39:$C$45-Παραδοχές!$B$39:$B$45+1)+(L14>=Παραδοχές!$B$39:$B$45)*(L14<=Παραδοχές!$C$39:$C$45)*(L14-Παραδοχές!$B$39:$B$45+1)) -> 12.45 | O14: =N14*$C14 -> 9.96
A15: =Σύνοψη!$B$22 -> 13 | B15: =Παραδοχές!$B$19 -> Πλευρικός Θήβας | C15: =Παραδοχές!$C$19 -> 1.8 | D15: =$A15*Παραδοχές!$C$26 -> 26 | E15: =D15*$C15 -> 46.8 | F15: =D15-SUMPRODUCT(Παραδοχές!$D$39:$D$45,(D15>Παραδοχές!$C$39:$C$45)*(Παραδοχές!$C$39:$C$45-Παραδοχές!$B$39:$B$45+1)+(D15>=Παραδοχές!$B$39:$B$45)*(D15<=Παραδοχές!$C$39:$C$45)*(D15-Παραδοχές!$B$39:$B$45+1)) -> 23.85 | G15: =F15*$C15 -> 42.93 | H15: =$A15*Παραδοχές!$D$26 -> 0 | I15: =H15*$C15 -> 0 | J15: =H15-SUMPRODUCT(Παραδοχές!$D$39:$D$45,(H15>Παραδοχές!$C$39:$C$45)*(Παραδοχές!$C$39:$C$45-Παραδοχές!$B$39:$B$45+1)+(H15>=Παραδοχές!$B$39:$B$45)*(H15<=Παραδοχές!$C$39:$C$45)*(H15-Παραδοχές!$B$39:$B$45+1)) -> 0 | K15: =J15*$C15 -> 0 | L15: =$A15*Παραδοχές!$E$26 -> 26 | M15: =L15*$C15 -> 46.8 | N15: =L15-SUMPRODUCT(Παραδοχές!$D$39:$D$45,(L15>Παραδοχές!$C$39:$C$45)*(Παραδοχές!$C$39:$C$45-Παραδοχές!$B$39:$B$45+1)+(L15>=Παραδοχές!$B$39:$B$45)*(L15<=Παραδοχές!$C$39:$C$45)*(L15-Παραδοχές!$B$39:$B$45+1)) -> 23.85 | O15: =N15*$C15 -> 42.93
A16: =Σύνοψη!$B$22 -> 13 | B16: =Παραδοχές!$B$20 -> Μετωπικός Αφιδνών | C16: =Παραδοχές!$C$20 -> 3.9 | D16: =$A16*Παραδοχές!$C$27 -> 26 | E16: =D16*$C16 -> 101.4 | F16: =D16-SUMPRODUCT(Παραδοχές!$D$39:$D$45,(D16>Παραδοχές!$C$39:$C$45)*(Παραδοχές!$C$39:$C$45-Παραδοχές!$B$39:$B$45+1)+(D16>=Παραδοχές!$B$39:$B$45)*(D16<=Παραδοχές!$C$39:$C$45)*(D16-Παραδοχές!$B$39:$B$45+1)) -> 23.85 | G16: =F16*$C16 -> 93.015 | H16: =$A16*Παραδοχές!$D$27 -> 26 | I16: =H16*$C16 -> 101.4 | J16: =H16-SUMPRODUCT(Παραδοχές!$D$39:$D$45,(H16>Παραδοχές!$C$39:$C$45)*(Παραδοχές!$C$39:$C$45-Παραδοχές!$B$39:$B$45+1)+(H16>=Παραδοχές!$B$39:$B$45)*(H16<=Παραδοχές!$C$39:$C$45)*(H16-Παραδοχές!$B$39:$B$45+1)) -> 23.85 | K16: =J16*$C16 -> 93.015 | L16: =$A16*Παραδοχές!$E$27 -> 13 | M16: =L16*$C16 -> 50.7 | N16: =L16-SUMPRODUCT(Παραδοχές!$D$39:$D$45,(L16>Παραδοχές!$C$39:$C$45)*(Παραδοχές!$C$39:$C$45-Παραδοχές!$B$39:$B$45+1)+(L16>=Παραδοχές!$B$39:$B$45)*(L16<=Παραδοχές!$C$39:$C$45)*(L16-Παραδοχές!$B$39:$B$45+1)) -> 12.45 | O16: =N16*$C16 -> 48.555
A17: =Σύνοψη!$B$22 -> 13 | B17: =Παραδοχές!$B$21 -> Μετωπικός Θήβας | C17: =Παραδοχές!$C$21 -> 4.55 | D17: =$A17*Παραδοχές!$C$28 -> 0 | E17: =D17*$C17 -> 0 | F17: =D17-SUMPRODUCT(Παραδοχές!$D$39:$D$45,(D17>Παραδοχές!$C$39:$C$45)*(Παραδοχές!$C$39:$C$45-Παραδοχές!$B$39:$B$45+1)+(D17>=Παραδοχές!$B$39:$B$45)*(D17<=Παραδοχές!$C$39:$C$45)*(D17-Παραδοχές!$B$39:$B$45+1)) -> 0 | G17: =F17*$C17 -> 0 | H17: =$A17*Παραδοχές!$D$28 -> 26 | I17: =H17*$C17 -> 118.3 | J17: =H17-SUMPRODUCT(Παραδοχές!$D$39:$D$45,(H17>Παραδοχές!$C$39:$C$45)*(Παραδοχές!$C$39:$C$45-Παραδοχές!$B$39:$B$45+1)+(H17>=Παραδοχές!$B$39:$B$45)*(H17<=Παραδοχές!$C$39:$C$45)*(H17-Παραδοχές!$B$39:$B$45+1)) -> 23.85 | K17: =J17*$C17 -> 108.5175 | L17: =$A17*Παραδοχές!$E$28 -> 0 | M17: =L17*$C17 -> 0 | N17: =L17-SUMPRODUCT(Παραδοχές!$D$39:$D$45,(L17>Παραδοχές!$C$39:$C$45)*(Παραδοχές!$C$39:$C$45-Παραδοχές!$B$39:$B$45+1)+(L17>=Παραδοχές!$B$39:$B$45)*(L17<=Παραδοχές!$C$39:$C$45)*(L17-Παραδοχές!$B$39:$B$45+1)) -> 0 | O17: =N17*$C17 -> 0
A18: =Σύνοψη!$B$23 -> 14 | B18: =Παραδοχές!$B$18 -> Πλευρικός Οινοφύτων | C18: =Παραδοχές!$C$18 -> 0.8 | D18: =$A18*Παραδοχές!$C$25 -> 0 | E18: =D18*$C18 -> 0 | F18: =D18-SUMPRODUCT(Παραδοχές!$D$39:$D$45,(D18>Παραδοχές!$C$39:$C$45)*(Παραδοχές!$C$39:$C$45-Παραδοχές!$B$39:$B$45+1)+(D18>=Παραδοχές!$B$39:$B$45)*(D18<=Παραδοχές!$C$39:$C$45)*(D18-Παραδοχές!$B$39:$B$45+1)) -> 0 | G18: =F18*$C18 -> 0 | H18: =$A18*Παραδοχές!$D$25 -> 0 | I18: =H18*$C18 -> 0 | J18: =H18-SUMPRODUCT(Παραδοχές!$D$39:$D$45,(H18>Παραδοχές!$C$39:$C$45)*(Παραδοχές!$C$39:$C$45-Παραδοχές!$B$39:$B$45+1)+(H18>=Παραδοχές!$B$39:$B$45)*(H18<=Παραδοχές!$C$39:$C$45)*(H18-Παραδοχές!$B$39:$B$45+1)) -> 0 | K18: =J18*$C18 -> 0 | L18: =$A18*Παραδοχές!$E$25 -> 14 | M18: =L18*$C18 -> 11.2 | N18: =L18-SUMPRODUCT(Παραδοχές!$D$39:$D$45,(L18>Παραδοχές!$C$39:$C$45)*(Παραδοχές!$C$39:$C$45-Παραδοχές!$B$39:$B$45+1)+(L18>=Παραδοχές!$B$39:$B$45)*(L18<=Παραδοχές!$C$39:$C$45)*(L18-Παραδοχές!$B$39:$B$45+1)) -> 13.35 | O18: =N18*$C18 -> 10.68
A19: =Σύνοψη!$B$23 -> 14 | B19: =Παραδοχές!$B$19 -> Πλευρικός Θήβας | C19: =Παραδοχές!$C$19 -> 1.8 | D19: =$A19*Παραδοχές!$C$26 -> 28 | E19: =D19*$C19 -> 50.4 | F19: =D19-SUMPRODUCT(Παραδοχές!$D$39:$D$45,(D19>Παραδοχές!$C$39:$C$45)*(Παραδοχές!$C$39:$C$45-Παραδοχές!$B$39:$B$45+1)+(D19>=Παραδοχές!$B$39:$B$45)*(D19<=Παραδοχές!$C$39:$C$45)*(D19-Παραδοχές!$B$39:$B$45+1)) -> 25.55 | G19: =F19*$C19 -> 45.99 | H19: =$A19*Παραδοχές!$D$26 -> 0 | I19: =H19*$C19 -> 0 | J19: =H19-SUMPRODUCT(Παραδοχές!$D$39:$D$45,(H19>Παραδοχές!$C$39:$C$45)*(Παραδοχές!$C$39:$C$45-Παραδοχές!$B$39:$B$45+1)+(H19>=Παραδοχές!$B$39:$B$45)*(H19<=Παραδοχές!$C$39:$C$45)*(H19-Παραδοχές!$B$39:$B$45+1)) -> 0 | K19: =J19*$C19 -> 0 | L19: =$A19*Παραδοχές!$E$26 -> 28 | M19: =L19*$C19 -> 50.4 | N19: =L19-SUMPRODUCT(Παραδοχές!$D$39:$D$45,(L19>Παραδοχές!$C$39:$C$45)*(Παραδοχές!$C$39:$C$45-Παραδοχές!$B$39:$B$45+1)+(L19>=Παραδοχές!$B$39:$B$45)*(L19<=Παραδοχές!$C$39:$C$45)*(L19-Παραδοχές!$B$39:$B$45+1)) -> 25.55 | O19: =N19*$C19 -> 45.99
A20: =Σύνοψη!$B$23 -> 14 | B20: =Παραδοχές!$B$20 -> Μετωπικός Αφιδνών | C20: =Παραδοχές!$C$20 -> 3.9 | D20: =$A20*Παραδοχές!$C$27 -> 28 | E20: =D20*$C20 -> 109.2 | F20: =D20-SUMPRODUCT(Παραδοχές!$D$39:$D$45,(D20>Παραδοχές!$C$39:$C$45)*(Παραδοχές!$C$39:$C$45-Παραδοχές!$B$39:$B$45+1)+(D20>=Παραδοχές!$B$39:$B$45)*(D20<=Παραδοχές!$C$39:$C$45)*(D20-Παραδοχές!$B$39:$B$45+1)) -> 25.55 | G20: =F20*$C20 -> 99.645 | H20: =$A20*Παραδοχές!$D$27 -> 28 | I20: =H20*$C20 -> 109.2 | J20: =H20-SUMPRODUCT(Παραδοχές!$D$39:$D$45,(H20>Παραδοχές!$C$39:$C$45)*(Παραδοχές!$C$39:$C$45-Παραδοχές!$B$39:$B$45+1)+(H20>=Παραδοχές!$B$39:$B$45)*(H20<=Παραδοχές!$C$39:$C$45)*(H20-Παραδοχές!$B$39:$B$45+1)) -> 25.55 | K20: =J20*$C20 -> 99.645 | L20: =$A20*Παραδοχές!$E$27 -> 14 | M20: =L20*$C20 -> 54.6 | N20: =L20-SUMPRODUCT(Παραδοχές!$D$39:$D$45,(L20>Παραδοχές!$C$39:$C$45)*(Παραδοχές!$C$39:$C$45-Παραδοχές!$B$39:$B$45+1)+(L20>=Παραδοχές!$B$39:$B$45)*(L20<=Παραδοχές!$C$39:$C$45)*(L20-Παραδοχές!$B$39:$B$45+1)) -> 13.35 | O20: =N20*$C20 -> 52.065
A21: =Σύνοψη!$B$23 -> 14 | B21: =Παραδοχές!$B$21 -> Μετωπικός Θήβας | C21: =Παραδοχές!$C$21 -> 4.55 | D21: =$A21*Παραδοχές!$C$28 -> 0 | E21: =D21*$C21 -> 0 | F21: =D21-SUMPRODUCT(Παραδοχές!$D$39:$D$45,(D21>Παραδοχές!$C$39:$C$45)*(Παραδοχές!$C$39:$C$45-Παραδοχές!$B$39:$B$45+1)+(D21>=Παραδοχές!$B$39:$B$45)*(D21<=Παραδοχές!$C$39:$C$45)*(D21-Παραδοχές!$B$39:$B$45+1)) -> 0 | G21: =F21*$C21 -> 0 | H21: =$A21*Παραδοχές!$D$28 -> 28 | I21: =H21*$C21 -> 127.4 | J21: =H21-SUMPRODUCT(Παραδοχές!$D$39:$D$45,(H21>Παραδοχές!$C$39:$C$45)*(Παραδοχές!$C$39:$C$45-Παραδοχές!$B$39:$B$45+1)+(H21>=Παραδοχές!$B$39:$B$45)*(H21<=Παραδοχές!$C$39:$C$45)*(H21-Παραδοχές!$B$39:$B$45+1)) -> 25.55 | K21: =J21*$C21 -> 116.2525 | L21: =$A21*Παραδοχές!$E$28 -> 0 | M21: =L21*$C21 -> 0 | N21: =L21-SUMPRODUCT(Παραδοχές!$D$39:$D$45,(L21>Παραδοχές!$C$39:$C$45)*(Παραδοχές!$C$39:$C$45-Παραδοχές!$B$39:$B$45+1)+(L21>=Παραδοχές!$B$39:$B$45)*(L21<=Παραδοχές!$C$39:$C$45)*(L21-Παραδοχές!$B$39:$B$45+1)) -> 0 | O21: =N21*$C21 -> 0
A22: =Σύνοψη!$B$24 -> 15 | B22: =Παραδοχές!$B$18 -> Πλευρικός Οινοφύτων | C22: =Παραδοχές!$C$18 -> 0.8 | D22: =$A22*Παραδοχές!$C$25 -> 0 | E22: =D22*$C22 -> 0 | F22: =D22-SUMPRODUCT(Παραδοχές!$D$39:$D$45,(D22>Παραδοχές!$C$39:$C$45)*(Παραδοχές!$C$39:$C$45-Παραδοχές!$B$39:$B$45+1)+(D22>=Παραδοχές!$B$39:$B$45)*(D22<=Παραδοχές!$C$39:$C$45)*(D22-Παραδοχές!$B$39:$B$45+1)) -> 0 | G22: =F22*$C22 -> 0 | H22: =$A22*Παραδοχές!$D$25 -> 0 | I22: =H22*$C22 -> 0 | J22: =H22-SUMPRODUCT(Παραδοχές!$D$39:$D$45,(H22>Παραδοχές!$C$39:$C$45)*(Παραδοχές!$C$39:$C$45-Παραδοχές!$B$39:$B$45+1)+(H22>=Παραδοχές!$B$39:$B$45)*(H22<=Παραδοχές!$C$39:$C$45)*(H22-Παραδοχές!$B$39:$B$45+1)) -> 0 | K22: =J22*$C22 -> 0 | L22: =$A22*Παραδοχές!$E$25 -> 15 | M22: =L22*$C22 -> 12 | N22: =L22-SUMPRODUCT(Παραδοχές!$D$39:$D$45,(L22>Παραδοχές!$C$39:$C$45)*(Παραδοχές!$C$39:$C$45-Παραδοχές!$B$39:$B$45+1)+(L22>=Παραδοχές!$B$39:$B$45)*(L22<=Παραδοχές!$C$39:$C$45)*(L22-Παραδοχές!$B$39:$B$45+1)) -> 14.25 | O22: =N22*$C22 -> 11.4
A23: =Σύνοψη!$B$24 -> 15 | B23: =Παραδοχές!$B$19 -> Πλευρικός Θήβας | C23: =Παραδοχές!$C$19 -> 1.8 | D23: =$A23*Παραδοχές!$C$26 -> 30 | E23: =D23*$C23 -> 54 | F23: =D23-SUMPRODUCT(Παραδοχές!$D$39:$D$45,(D23>Παραδοχές!$C$39:$C$45)*(Παραδοχές!$C$39:$C$45-Παραδοχές!$B$39:$B$45+1)+(D23>=Παραδοχές!$B$39:$B$45)*(D23<=Παραδοχές!$C$39:$C$45)*(D23-Παραδοχές!$B$39:$B$45+1)) -> 27.25 | G23: =F23*$C23 -> 49.05 | H23: =$A23*Παραδοχές!$D$26 -> 0 | I23: =H23*$C23 -> 0 | J23: =H23-SUMPRODUCT(Παραδοχές!$D$39:$D$45,(H23>Παραδοχές!$C$39:$C$45)*(Παραδοχές!$C$39:$C$45-Παραδοχές!$B$39:$B$45+1)+(H23>=Παραδοχές!$B$39:$B$45)*(H23<=Παραδοχές!$C$39:$C$45)*(H23-Παραδοχές!$B$39:$B$45+1)) -> 0 | K23: =J23*$C23 -> 0 | L23: =$A23*Παραδοχές!$E$26 -> 30 | M23: =L23*$C23 -> 54 | N23: =L23-SUMPRODUCT(Παραδοχές!$D$39:$D$45,(L23>Παραδοχές!$C$39:$C$45)*(Παραδοχές!$C$39:$C$45-Παραδοχές!$B$39:$B$45+1)+(L23>=Παραδοχές!$B$39:$B$45)*(L23<=Παραδοχές!$C$39:$C$45)*(L23-Παραδοχές!$B$39:$B$45+1)) -> 27.25 | O23: =N23*$C23 -> 49.05
A24: =Σύνοψη!$B$24 -> 15 | B24: =Παραδοχές!$B$20 -> Μετωπικός Αφιδνών | C24: =Παραδοχές!$C$20 -> 3.9 | D24: =$A24*Παραδοχές!$C$27 -> 30 | E24: =D24*$C24 -> 117 | F24: =D24-SUMPRODUCT(Παραδοχές!$D$39:$D$45,(D24>Παραδοχές!$C$39:$C$45)*(Παραδοχές!$C$39:$C$45-Παραδοχές!$B$39:$B$45+1)+(D24>=Παραδοχές!$B$39:$B$45)*(D24<=Παραδοχές!$C$39:$C$45)*(D24-Παραδοχές!$B$39:$B$45+1)) -> 27.25 | G24: =F24*$C24 -> 106.275 | H24: =$A24*Παραδοχές!$D$27 -> 30 | I24: =H24*$C24 -> 117 | J24: =H24-SUMPRODUCT(Παραδοχές!$D$39:$D$45,(H24>Παραδοχές!$C$39:$C$45)*(Παραδοχές!$C$39:$C$45-Παραδοχές!$B$39:$B$45+1)+(H24>=Παραδοχές!$B$39:$B$45)*(H24<=Παραδοχές!$C$39:$C$45)*(H24-Παραδοχές!$B$39:$B$45+1)) -> 27.25 | K24: =J24*$C24 -> 106.275 | L24: =$A24*Παραδοχές!$E$27 -> 15 | M24: =L24*$C24 -> 58.5 | N24: =L24-SUMPRODUCT(Παραδοχές!$D$39:$D$45,(L24>Παραδοχές!$C$39:$C$45)*(Παραδοχές!$C$39:$C$45-Παραδοχές!$B$39:$B$45+1)+(L24>=Παραδοχές!$B$39:$B$45)*(L24<=Παραδοχές!$C$39:$C$45)*(L24-Παραδοχές!$B$39:$B$45+1)) -> 14.25 | O24: =N24*$C24 -> 55.575
A25: =Σύνοψη!$B$24 -> 15 | B25: =Παραδοχές!$B$21 -> Μετωπικός Θήβας | C25: =Παραδοχές!$C$21 -> 4.55 | D25: =$A25*Παραδοχές!$C$28 -> 0 | E25: =D25*$C25 -> 0 | F25: =D25-SUMPRODUCT(Παραδοχές!$D$39:$D$45,(D25>Παραδοχές!$C$39:$C$45)*(Παραδοχές!$C$39:$C$45-Παραδοχές!$B$39:$B$45+1)+(D25>=Παραδοχές!$B$39:$B$45)*(D25<=Παραδοχές!$C$39:$C$45)*(D25-Παραδοχές!$B$39:$B$45+1)) -> 0 | G25: =F25*$C25 -> 0 | H25: =$A25*Παραδοχές!$D$28 -> 30 | I25: =H25*$C25 -> 136.5 | J25: =H25-SUMPRODUCT(Παραδοχές!$D$39:$D$45,(H25>Παραδοχές!$C$39:$C$45)*(Παραδοχές!$C$39:$C$45-Παραδοχές!$B$39:$B$45+1)+(H25>=Παραδοχές!$B$39:$B$45)*(H25<=Παραδοχές!$C$39:$C$45)*(H25-Παραδοχές!$B$39:$B$45+1)) -> 27.25 | K25: =J25*$C25 -> 123.9875 | L25: =$A25*Παραδοχές!$E$28 -> 0 | M25: =L25*$C25 -> 0 | N25: =L25-SUMPRODUCT(Παραδοχές!$D$39:$D$45,(L25>Παραδοχές!$C$39:$C$45)*(Παραδοχές!$C$39:$C$45-Παραδοχές!$B$39:$B$45+1)+(L25>=Παραδοχές!$B$39:$B$45)*(L25<=Παραδοχές!$C$39:$C$45)*(L25-Παραδοχές!$B$39:$B$45+1)) -> 0 | O25: =N25*$C25 -> 0
A27: Οι γραμμές 6–9 αφορούν τον μέσο μήνα (Παραδοχές). Οι γραμμές 10–25 αφορούν τους μήνες του πίνακα 3 της Σύνοψης.
